Workbook

Sheet MODIFICAR CODIGOS 
A1: CODIGO | B1: PRODUCTO MODIFICAR | C1: Estiba | D1: Piso | E1: CAJAS | G1: CODIGO | H1: PRODUCTO MODIFICAR | I1: Estiba | J1: Piso
A2: 160052 | B2: COCA-COLA 6,5OZ VIR(30) | C2: 45 | D2: 9 | E2: 30 | G2: 160052 | H2: COCA-COLA 6,5OZ VIR(30) | I2: 45 | J2: 9 | K2: 30
C3: 45 | D3: 9 | E3: 30 | G3: 160646 | H3: COCA-COLA ZERO 6,5OZ VIR(30) | I3: 45 | J3: 9 | K3: 1
A4: 56702 | B4: QUATRO TJA 6,5OZ VIR(30) | C4: 45 | D4: 9 | E4: 30 | G4: 56702 | H4: QUATRO TJA 6,5OZ VIR(30) | I4: 45 | J4: 9 | K4: 30
C5: 45 | D5: 9 | E5: 30 | H5: PREMIO RJ 6 OZ VIR(30) | I5: 45 | J5: 9
A6: 160069 | B6: SPRITE LL6,5 OZ | C6: 45 | D6: 9 | E6: 30 | G6: 160069 | H6: SPRITE LL6,5 OZ | I6: 45 | J6: 9 | K6: 30
C7: 45 | D7: 9 | E7: 30 | G7: 160176 | H7: FANTA NARANJA 250 ML RGB | I7: 45 | J7: 9 | K7: 1
C8: 45 | D8: 9 | E8: 30 | G8: 160177 | H8: FANTA MANZANA 250 ML RGB | I8: 45 | J8: 9 | K8: 1
C9: 45 | D9: 9 | E9: 30 | G9: 160361 | H9: FANTA UVA 250 ML RGB | I9: 45 | J9: 9 | K9: 1
A10: 56623 | B10: PREMIO ROJO 250 ML RGB | C10: 45 | D10: 9 | E10: 30 | G10: 56623 | H10: PREMIO ROJO 250 ML RGB | I10: 45 | J10: 9 | K10: 30
A12: 160053 | B12: COCA-COLA 350ML VIR(30) | C12: 45 | D12: 9 | E12: 30 | G12: 160053 | H12: COCA-COLA 350ML VIR(30) | I12: 45 | J12: 9 | K12: 30
A13: 135763 | B13: COCA COLA ZERO 350 ML VIR | C13: 45 | D13: 9 | E13: 30 | G13: 135763 | H13: COCA COLA ZERO 350 ML VIR | I13: 45 | J13: 9 | K13: 30
A14: 56622 | B14: PREMIO ROJO 350 ML (30) | C14: 45 | D14: 9 | E14: 30 | G14: 56622 | H14: PREMIO ROJO 350 ML (30) | I14: 45 | J14: 9 | K14: 30
A15: 56705 | B15: QUATRO TJA 350ML VIR(30) | C15: 45 | D15: 9 | E15: 30 | G15: 56705 | H15: QUATRO TJA 350ML VIR(30) | I15: 45 | J15: 9 | K15: 30
A16: 160070 | B16: SPRITE LL 350ML VIR(30) | C16: 45 | D16: 9 | E16: 30 | G16: 160070 | H16: SPRITE LL 350ML VIR(30) | I16: 45 | J16: 9 | K16: 30
A17: 160033 | B17: SCHWEPPES SODA 350 ML VIR (30) | C17: 45 | D17: 9 | E17: 30 | G17: 160033 | H17: SCHWEPPES SODA 350 ML VIR (30) | I17: 45 | J17: 9 | K17: 30
C18: 45 | D18: 9 | E18: 30 | G18: 160009 | H18: FANTA NARANJA 350ML (30) VIR | I18: 45 | J18: 9 | K18: 1
C19: 45 | D19: 9 | E19: 30 | G19: 160010 | H19: FANTA MANZANA 350ML (30) VIR | I19: 45 | J19: 9 | K19: 1
C20: 45 | D20: 9 | E20: 30 | G20: 160624 | H20: DEL VALLE FRUTAL MANGO 350 ML | I20: 45 | J20: 9 | K20: 1
C21: 45 | D21: 9 | E21: 30 | G21: 160625 | H21: DEL VALLE FRUTAL GUAYABA 350 ML | I21: 45 | J21: 9 | K21: 1
C22: 45 | D22: 9 | E22: 30 | G22: 160626 | H22: DEL VALLE FRUTAL MANDAR | I22: 45 | J22: 9 | K22: 1
C23: 45 | D23: 9 | E23: 30 | G23: 119945 | H23: FRUTAL MANGOFRS 350 ML (30) | I23: 45 | J23: 9 | K23: 1
A24: 135666 | B24: COCA COLA 1.25LT VIR(12) | C24: 40 | D24: 10 | E24: 12 | G24: 135666 | H24: COCA COLA 1.25LT VIR(12) | I24: 40 | J24: 10 | K24: 12
C25: 40 | D25: 10 | E25: 12 | G25: 5666 | H25: COCA COLA 1.25LT PET(12) | I25: 70 | J25: 14 | K25: 1
A27: 136159 | B27: COCA-COLA SO 1 LT NR (12) | C27: 75 | D27: 15 | E27: 12 | G27: 136159 | H27: COCA-COLA SO 1 LT NR (12) | I27: 75 | J27: 15 | K27: 12
A28: 136113 | B28: ESPEJO CCSO 1.5LT PET(12) | C28: 65 | D28: 13 | E28: 12 | G28: 136113 | H28: ESPEJO CCSO 1.5LT PET(12) | I28: 65 | J28: 13 | K28: 12
A29: 135664 | B29: COCA-COLA 1.5 LT NR (12) Nvo | C29: 65 | D29: 13 | E29: 12 | G29: 135664 | H29: COCA-COLA 1.5 LT NR (12) Nvo | I29: 65 | J29: 13 | K29: 12
A30: 135757 | B30: COCA COLA ZERO 1,5 NR (12) | C30: 65 | D30: 13 | E30: 12 | G30: 135757 | H30: COCA COLA ZERO 1,5 NR (12) | I30: 65 | J30: 13 | K30: 12
A31: 56651 | B31: PREMIO ROJO 1.5 L | C31: 65 | D31: 13 | E31: 12 | G31: 56651 | H31: PREMIO ROJO 1.5 L | I31: 65 | J31: 13 | K31: 12
A32: 56709 | B32: QUATRO 1,5LT | C32: 65 | D32: 13 | E32: 12 | G32: 56709 | H32: QUATRO 1,5LT | I32: 65 | J32: 13 | K32: 12
A33: 160102 | B33: SRITE LIMA LIMON 1,5LT | C33: 65 | D33: 13 | E33: 12 | G33: 160102 | H33: SRITE LIMA LIMON 1,5LT | I33: 65 | J33: 13 | K33: 12
A34: 160100 | B34: SCHEPPES GINGER 1,5 LTS | C34: 65 | D34: 13 | E34: 12 | G34: 160100 | H34: SCHEPPES GINGER 1,5 LTS | I34: 65 | J34: 13 | K34: 12
A35: 160101 | B35: SCHEPPES SODA 1,5 LTS | C35: 65 | D35: 13 | E35: 12 | G35: 160101 | H35: SCHEPPES SODA 1,5 LTS | I35: 65 | J35: 13 | K35: 12
A36: 160099 | B36: KOLA ROMA 1,5 LTS | C36: 65 | D36: 13 | E36: 12 | G36: 160099 | H36: KOLA ROMA 1,5 LTS | I36: 65 | J36: 13 | K36: 12
E38: 1 | G38: 160657 | H38: COCA COLA SABOR LIGERO 1,5 LTS | I38: 65 | J38: 13 | K38: 1
A39: 136133 | B39: COCA COLA 2.25L PET(8) EINSTEIN | C39: 60 | D39: 12 | E39: 8 | G39: 136133 | H39: COCA COLA 2.25L PET(8)EINSTEIN | I39: 60 | J39: 12 | K39: 8
E40: 1 | G40: 56572 | H40: QUATRO TORONJA 1,5 LTS | I40: 65 | J40: 13 | K40: 1
E41: 1 | G41: 160130 | H41: KOLA ROMAN 1.75L | I41: 55 | J41: 11 | K41: 1
E42: 1 | G42: 135756 | H42: COCA COLA SA 1.75 L PET (12) | I42: 55 | J42: 11 | K42: 1
E43: 1 | G43: 135695 | H43: COCA COLA SO 1.75 L | I43: 55 | J43: 11 | K43: 1
...

Sheet PLANTILLA INV. PISO (0)
A1: CODIGO | B1: PRODUCTO | C1: Estiba | D1: Piso | E1: PACAS | F1: ESTIBAS | L1: PISO | P1: CAJAS | S1: UND | U1: TOTAL | V1: cajas | W1: und | X1: DECIMALES | Y1: HOY | Z1: FECHA + | AA1: FECHA TPM | AB1: DIAS X VENCER
A2: ='MODIFICAR CODIGOS '!A2 -> 160052 | B2: ='MODIFICAR CODIGOS '!B2 -> COCA-COLA 6,5OZ VIR(30) | C2: ='MODIFICAR CODIGOS '!C2 -> 45 | D2: ='MODIFICAR CODIGOS '!D2 -> 9 | E2: ='MODIFICAR CODIGOS '!E2 -> 30 | I2: 2 | Q2: 9 | S2: 5 | U2: =(F2*C2+G2*C2+H2*C2+I2*C2+J2*C2+K2*C2+L2*D2+M2*D2+N2*D2+O2*D2+P2*1+Q2*1+R2*1+(TRUNC((S2+T2)/E2)))+(((S2+T2)/E2-TRUNC((S2+T2)/E2))*E2)/100 -> 99.05 | V2: =(F2*C2+G2*C2+H2*C2+I2*C2+J2*C2+K2*C2+L2*D2+M2*D2+N2*D2+O2*D2+P2*1+Q2*1+R2*1+(TRUNC((S2+T2)/E2))) -> 99 | W2: =(((S2+T2)/E2-TRUNC((S2+T2)/E2))*E2) -> 5 | X2: =V2+W2/E2 -> 99.166667 | Y2: =TODAY() -> 46104 | Z2: 46178 | AA2: 46178 | AB2: =AA2-Y2 -> 74
A3: ='MODIFICAR CODIGOS '!A3 -> 0 | B3: ='MODIFICAR CODIGOS '!B3 -> 0 | C3: ='MODIFICAR CODIGOS '!C3 -> 45 | D3: ='MODIFICAR CODIGOS '!D3 -> 9 | E3: 1 | U3: =(F3*C3+G3*C3+H3*C3+I3*C3+J3*C3+K3*C3+L3*D3+M3*D3+N3*D3+O3*D3+P3*1+Q3*1+R3*1+(TRUNC((S3+T3)/E3)))+(((S3+T3)/E3-TRUNC((S3+T3)/E3))*E3)/100 -> 0 | V3: =(F3*C3+G3*C3+H3*C3+I3*C3+J3*C3+K3*C3+L3*D3+M3*D3+N3*D3+O3*D3+P3*1+Q3*1+R3*1+(TRUNC((S3+T3)/E3))) -> 0 | W3: =(((S3+T3)/E3-TRUNC((S3+T3)/E3))*E3) -> 0 | X3: =V3+W3/E3 -> 0 | Y3: =TODAY() -> 46104 | AB3: =AA3-Y3 -> -46104
A4: ='MODIFICAR CODIGOS '!A4 -> 56702 | B4: ='MODIFICAR CODIGOS '!B4 -> QUATRO TJA 6,5OZ VIR(30) | C4: ='MODIFICAR CODIGOS '!C4 -> 45 | D4: ='MODIFICAR CODIGOS '!D4 -> 9 | E4: ='MODIFICAR CODIGOS '!E4 -> 30 | I4: 1 | Q4: 13 | S4: 21 | U4: =(F4*C4+G4*C4+H4*C4+I4*C4+J4*C4+K4*C4+L4*D4+M4*D4+N4*D4+O4*D4+P4*1+Q4*1+R4*1+(TRUNC((S4+T4)/E4)))+(((S4+T4)/E4-TRUNC((S4+T4)/E4))*E4)/100 -> 58.21 | V4: =(F4*C4+G4*C4+H4*C4+I4*C4+J4*C4+K4*C4+L4*D4+M4*D4+N4*D4+O4*D4+P4*1+Q4*1+R4*1+(TRUNC((S4+T4)/E4))) -> 58 | W4: =(((S4+T4)/E4-TRUNC((S4+T4)/E4))*E4) -> 21 | X4: =V4+W4/E4 -> 58.7 | Y4: =TODAY() -> 46104 | AB4: =AA4-Y4 -> -46104
A5: ='MODIFICAR CODIGOS '!A5 -> 0 | B5: ='MODIFICAR CODIGOS '!B5 -> 0 | C5: ='MODIFICAR CODIGOS '!C5 -> 45 | D5: ='MODIFICAR CODIGOS '!D5 -> 9 | E5: 1 | U5: =(F5*C5+G5*C5+H5*C5+I5*C5+J5*C5+K5*C5+L5*D5+M5*D5+N5*D5+O5*D5+P5*1+Q5*1+R5*1+(TRUNC((S5+T5)/E5)))+(((S5+T5)/E5-TRUNC((S5+T5)/E5))*E5)/100 -> 0 | V5: =(F5*C5+G5*C5+H5*C5+I5*C5+J5*C5+K5*C5+L5*D5+M5*D5+N5*D5+O5*D5+P5*1+Q5*1+R5*1+(TRUNC((S5+T5)/E5))) -> 0 | W5: =(((S5+T5)/E5-TRUNC((S5+T5)/E5))*E5) -> 0 | X5: =V5+W5/E5 -> 0 | Y5: =TODAY() -> 46104 | AB5: =AA5-Y5 -> -46104
A6: ='MODIFICAR CODIGOS '!A6 -> 160069 | B6: ='MODIFICAR CODIGOS '!B6 -> SPRITE LL6,5 OZ | C6: ='MODIFICAR CODIGOS '!C6 -> 45 | D6: ='MODIFICAR CODIGOS '!D6 -> 9 | E6: ='MODIFICAR CODIGOS '!E6 -> 30 | I6: 2 | Q6: 7 | S6: 8 | U6: =(F6*C6+G6*C6+H6*C6+I6*C6+J6*C6+K6*C6+L6*D6+M6*D6+N6*D6+O6*D6+P6*1+Q6*1+R6*1+(TRUNC((S6+T6)/E6)))+(((S6+T6)/E6-TRUNC((S6+T6)/E6))*E6)/100 -> 97.08 | V6: =(F6*C6+G6*C6+H6*C6+I6*C6+J6*C6+K6*C6+L6*D6+M6*D6+N6*D6+O6*D6+P6*1+Q6*1+R6*1+(TRUNC((S6+T6)/E6))) -> 97 | W6: =(((S6+T6)/E6-TRUNC((S6+T6)/E6))*E6) -> 8 | X6: =V6+W6/E6 -> 97.266667 | Y6: =TODAY() -> 46104 | AB6: =AA6-Y6 -> -46104
A7: ='MODIFICAR CODIGOS '!A7 -> 0 | B7: ='MODIFICAR CODIGOS '!B7 -> 0 | C7: ='MODIFICAR CODIGOS '!C7 -> 45 | D7: ='MODIFICAR CODIGOS '!D7 -> 9 | E7: 1 | U7: =(F7*C7+G7*C7+H7*C7+I7*C7+J7*C7+K7*C7+L7*D7+M7*D7+N7*D7+O7*D7+P7*1+Q7*1+R7*1+(TRUNC((S7+T7)/E7)))+(((S7+T7)/E7-TRUNC((S7+T7)/E7))*E7)/100 -> 0 | V7: =(F7*C7+G7*C7+H7*C7+I7*C7+J7*C7+K7*C7+L7*D7+M7*D7+N7*D7+O7*D7+P7*1+Q7*1+R7*1+(TRUNC((S7+T7)/E7))) -> 0 | W7: =(((S7+T7)/E7-TRUNC((S7+T7)/E7))*E7) -> 0 | X7: =V7+W7/E7 -> 0 | Y7: =TODAY() -> 46104 | AB7: =AA7-Y7 -> -46104
A8: ='MODIFICAR CODIGOS '!A8 -> 0 | B8: ='MODIFICAR CODIGOS '!B8 -> 0 | C8: ='MODIFICAR CODIGOS '!C8 -> 45 | D8: ='MODIFICAR CODIGOS '!D8 -> 9 | E8: 1 | U8: =(F8*C8+G8*C8+H8*C8+I8*C8+J8*C8+K8*C8+L8*D8+M8*D8+N8*D8+O8*D8+P8*1+Q8*1+R8*1+(TRUNC((S8+T8)/E8)))+(((S8+T8)/E8-TRUNC((S8+T8)/E8))*E8)/100 -> 0 | V8: =(F8*C8+G8*C8+H8*C8+I8*C8+J8*C8+K8*C8+L8*D8+M8*D8+N8*D8+O8*D8+P8*1+Q8*1+R8*1+(TRUNC((S8+T8)/E8))) -> 0 | W8: =(((S8+T8)/E8-TRUNC((S8+T8)/E8))*E8) -> 0 | X8: =V8+W8/E8 -> 0 | Y8: =TODAY() -> 46104 | AB8: =AA8-Y8 -> -46104
A9: ='MODIFICAR CODIGOS '!A9 -> 0 | B9: ='MODIFICAR CODIGOS '!B9 -> 0 | C9: ='MODIFICAR CODIGOS '!C9 -> 45 | D9: ='MODIFICAR CODIGOS '!D9 -> 9 | E9: 1 | U9: =(F9*C9+G9*C9+H9*C9+I9*C9+J9*C9+K9*C9+L9*D9+M9*D9+N9*D9+O9*D9+P9*1+Q9*1+R9*1+(TRUNC((S9+T9)/E9)))+(((S9+T9)/E9-TRUNC((S9+T9)/E9))*E9)/100 -> 0 | V9: =(F9*C9+G9*C9+H9*C9+I9*C9+J9*C9+K9*C9+L9*D9+M9*D9+N9*D9+O9*D9+P9*1+Q9*1+R9*1+(TRUNC((S9+T9)/E9))) -> 0 | W9: =(((S9+T9)/E9-TRUNC((S9+T9)/E9))*E9) -> 0 | X9: =V9+W9/E9 -> 0 | Y9: =TODAY() -> 46104 | AB9: =AA9-Y9 -> -46104
A10: ='MODIFICAR CODIGOS '!A10 -> 56623 | B10: ='MODIFICAR CODIGOS '!B10 -> PREMIO ROJO 250 ML RGB | C10: ='MODIFICAR CODIGOS '!C10 -> 45 | D10: ='MODIFICAR CODIGOS '!D10 -> 9 | E10: ='MODIFICAR CODIGOS '!E10 -> 30 | U10: =(F10*C10+G10*C10+H10*C10+I10*C10+J10*C10+K10*C10+L10*D10+M10*D10+N10*D10+O10*D10+P10*1+Q10*1+R10*1+(TRUNC((S10+T10)/E10)))+(((S10+T10)/E10-TRUNC((S10+T10)/E10))*E10)/100 -> 0 | V10: =(F10*C10+G10*C10+H10*C10+I10*C10+J10*C10+K10*C10+L10*D10+M10*D10+N10*D10+O10*D10+P10*1+Q10*1+R10*1+(TRUNC((S10+T10)/E10))) -> 0 | W10: =(((S10+T10)/E10-TRUNC((S10+T10)/E10))*E10) -> 0 | X10: =V10+W10/E10 -> 0 | Y10: =TODAY() -> 46104 | AB10: =AA10-Y10 -> -46104
A11: * | V11: =(F11*C11+G11*C11+H11*C11+I11*C11+J11*C11+K11*C11+L11*D11+M11*D11+N11*D11+O11*D11+P11*1+Q11*1+R11*1+(TRUNC((S11+T11)/E11))) -> #DIV/0! | W11: =(((S11+T11)/E11-TRUNC((S11+T11)/E11))*E11) -> #DIV/0! | AB11: =AA11-Y11 -> 0
A12: ='MODIFICAR CODIGOS '!A12 -> 160053 | B12: ='MODIFICAR CODIGOS '!B12 -> COCA-COLA 350ML VIR(30) | C12: ='MODIFICAR CODIGOS '!C12 -> 45 | D12: ='MODIFICAR CODIGOS '!D12 -> 9 | E12: ='MODIFICAR CODIGOS '!E12 -> 30 | Q12: 5 | R12: 37 | S12: 10 | U12: =(F12*C12+G12*C12+H12*C12+I12*C12+J12*C12+K12*C12+L12*D12+M12*D12+N12*D12+O12*D12+P12*1+Q12*1+R12*1+(TRUNC((S12+T12)/E12)))+(((S12+T12)/E12-TRUNC((S12+T12)/E12))*E12)/100 -> 42.1 | V12: =(F12*C12+G12*C12+H12*C12+I12*C12+J12*C12+K12*C12+L12*D12+M12*D12+N12*D12+O12*D12+P12*1+Q12*1+R12*1+(TRUNC((S12+T12)/E12))) -> 42 | W12: =(((S12+T12)/E12-TRUNC((S12+T12)/E12))*E12) -> 10 | X12: =V12+W12/E12 -> 42.333333 | Y12: =TODAY() -> 46104 | AB12: =AA12-Y12 -> -46104
A13: ='MODIFICAR CODIGOS '!A13 -> 135763 | B13: ='MODIFICAR CODIGOS '!B13 -> COCA COLA ZERO 350 ML VIR | C13: ='MODIFICAR CODIGOS '!C13 -> 45 | D13: ='MODIFICAR CODIGOS '!D13 -> 9 | E13: ='MODIFICAR CODIGOS '!E13 -> 30 | Q13: 18 | S13: 24 | U13: =(F13*C13+G13*C13+H13*C13+I13*C13+J13*C13+K13*C13+L13*D13+M13*D13+N13*D13+O13*D13+P13*1+Q13*1+R13*1+(TRUNC((S13+T13)/E13)))+(((S13+T13)/E13-TRUNC((S13+T13)/E13))*E13)/100 -> 18.24 | V13: =(F13*C13+G13*C13+H13*C13+I13*C13+J13*C13+K13*C13+L13*D13+M13*D13+N13*D13+O13*D13+P13*1+Q13*1+R13*1+(TRUNC((S13+T13)/E13))) -> 18 | W13: =(((S13+T13)/E13-TRUNC((S13+T13)/E13))*E13) -> 24 | X13: =V13+W13/E13 -> 18.8 | Y13: =TODAY() -> 46104 | AB13: =AA13-Y13 -> -46104
A14: ='MODIFICAR CODIGOS '!A14 -> 56622 | B14: ='MODIFICAR CODIGOS '!B14 -> PREMIO ROJO 350 ML (30) | C14: ='MODIFICAR CODIGOS '!C14 -> 45 | D14: ='MODIFICAR CODIGOS '!D14 -> 9 | E14: ='MODIFICAR CODIGOS '!E14 -> 30 | Q14: 35 | S14: 20 | U14: =(F14*C14+G14*C14+H14*C14+I14*C14+J14*C14+K14*C14+L14*D14+M14*D14+N14*D14+O14*D14+P14*1+Q14*1+R14*1+(TRUNC((S14+T14)/E14)))+(((S14+T14)/E14-TRUNC((S14+T14)/E14))*E14)/100 -> 35.2 | V14: =(F14*C14+G14*C14+H14*C14+I14*C14+J14*C14+K14*C14+L14*D14+M14*D14+N14*D14+O14*D14+P14*1+Q14*1+R14*1+(TRUNC((S14+T14)/E14))) -> 35 | W14: =(((S14+T14)/E14-TRUNC((S14+T14)/E14))*E14) -> 20 | X14: =V14+W14/E14 -> 35.666667 | Y14: =TODAY() -> 46104 | AB14: =AA14-Y14 -> -46104
A15: ='MODIFICAR CODIGOS '!A15 -> 56705 | B15: ='MODIFICAR CODIGOS '!B15 -> QUATRO TJA 350ML VIR(30) | C15: ='MODIFICAR CODIGOS '!C15 -> 45 | D15: ='MODIFICAR CODIGOS '!D15 -> 9 | E15: ='MODIFICAR CODIGOS '!E15 -> 30 | Q15: 32 | S15: 25 | U15: =(F15*C15+G15*C15+H15*C15+I15*C15+J15*C15+K15*C15+L15*D15+M15*D15+N15*D15+O15*D15+P15*1+Q15*1+R15*1+(TRUNC((S15+T15)/E15)))+(((S15+T15)/E15-TRUNC((S15+T15)/E15))*E15)/100 -> 32.25 | V15: =(F15*C15+G15*C15+H15*C15+I15*C15+J15*C15+K15*C15+L15*D15+M15*D15+N15*D15+O15*D15+P15*1+Q15*1+R15*1+(TRUNC((S15+T15)/E15))) -> 32 | W15: =(((S15+T15)/E15-TRUNC((S15+T15)/E15))*E15) -> 25 | X15: =V15+W15/E15 -> 32.833333 | Y15: =TODAY() -> 46104 | AB15: =AA15-Y15 -> -46104
A16: ='MODIFICAR CODIGOS '!A16 -> 160070 | B16: ='MODIFICAR CODIGOS '!B16 -> SPRITE LL 350ML VIR(30) | C16: ='MODIFICAR CODIGOS '!C16 -> 45 | D16: ='MODIFICAR CODIGOS '!D16 -> 9 | E16: ='MODIFICAR CODIGOS '!E16 -> 30 | Q16: 43 | S16: 25 | U16: =(F16*C16+G16*C16+H16*C16+I16*C16+J16*C16+K16*C16+L16*D16+M16*D16+N16*D16+O16*D16+P16*1+Q16*1+R16*1+(TRUNC((S16+T16)/E16)))+(((S16+T16)/E16-TRUNC((S16+T16)/E16))*E16)/100 -> 43.25 | V16: =(F16*C16+G16*C16+H16*C16+I16*C16+J16*C16+K16*C16+L16*D16+M16*D16+N16*D16+O16*D16+P16*1+Q16*1+R16*1+(TRUNC((S16+T16)/E16))) -> 43 | W16: =(((S16+T16)/E16-TRUNC((S16+T16)/E16))*E16) -> 25 | X16: =V16+W16/E16 -> 43.833333 | Y16: =TODAY() -> 46104 | AB16: =AA16-Y16 -> -46104
A17: ='MODIFICAR CODIGOS '!A17 -> 160033 | B17: ='MODIFICAR CODIGOS '!B17 -> SCHWEPPES SODA 350 ML VIR (30) | C17: ='MODIFICAR CODIGOS '!C17 -> 45 | D17: ='MODIFICAR CODIGOS '!D17 -> 9 | E17: ='MODIFICAR CODIGOS '!E17 -> 30 | Q17: 3 | S17: 9 | U17: =(F17*C17+G17*C17+H17*C17+I17*C17+J17*C17+K17*C17+L17*D17+M17*D17+N17*D17+O17*D17+P17*1+Q17*1+R17*1+(TRUNC((S17+T17)/E17)))+(((S17+T17)/E17-TRUNC((S17+T17)/E17))*E17)/100 -> 3.09 | V17: =(F17*C17+G17*C17+H17*C17+I17*C17+J17*C17+K17*C17+L17*D17+M17*D17+N17*D17+O17*D17+P17*1+Q17*1+R17*1+(TRUNC((S17+T17)/E17))) -> 3 | W17: =(((S17+T17)/E17-TRUNC((S17+T17)/E17))*E17) -> 9 | X17: =V17+W17/E17 -> 3.3 | Y17: =TODAY() -> 46104 | AB17: =AA17-Y17 -> -46104
A18: ='MODIFICAR CODIGOS '!A18 -> 0 | B18: ='MODIFICAR CODIGOS '!B18 -> 0 | C18: ='MODIFICAR CODIGOS '!C18 -> 45 | D18: ='MODIFICAR CODIGOS '!D18 -> 9 | E18: ='MODIFICAR CODIGOS '!E18 -> 30 | U18: =(F18*C18+G18*C18+H18*C18+I18*C18+J18*C18+K18*C18+L18*D18+M18*D18+N18*D18+O18*D18+P18*1+Q18*1+R18*1+(TRUNC((S18+T18)/E18)))+(((S18+T18)/E18-TRUNC((S18+T18)/E18))*E18)/100 -> 0 | V18: =(F18*C18+G18*C18+H18*C18+I18*C18+J18*C18+K18*C18+L18*D18+M18*D18+N18*D18+O18*D18+P18*1+Q18*1+R18*1+(TRUNC((S18+T18)/E18))) -> 0 | W18: =(((S18+T18)/E18-TRUNC((S18+T18)/E18))*E18) -> 0 | X18: =V18+W18/E18 -> 0 | Y18: =TODAY() -> 46104 | AB18: =AA18-Y18 -> -46104
A19: ='MODIFICAR CODIGOS '!A19 -> 0 | B19: ='MODIFICAR CODIGOS '!B19 -> 0 | C19: ='MODIFICAR CODIGOS '!C19 -> 45 | D19: ='MODIFICAR CODIGOS '!D19 -> 9 | E19: ='MODIFICAR CODIGOS '!E19 -> 30 | U19: =(F19*C19+G19*C19+H19*C19+I19*C19+J19*C19+K19*C19+L19*D19+M19*D19+N19*D19+O19*D19+P19*1+Q19*1+R19*1+(TRUNC((S19+T19)/E19)))+(((S19+T19)/E19-TRUNC((S19+T19)/E19))*E19)/100 -> 0 | V19: =(F19*C19+G19*C19+H19*C19+I19*C19+J19*C19+K19*C19+L19*D19+M19*D19+N19*D19+O19*D19+P19*1+Q19*1+R19*1+(TRUNC((S19+T19)/E19))) -> 0 | W19: =(((S19+T19)/E19-TRUNC((S19+T19)/E19))*E19) -> 0 | X19: =V19+W19/E19 -> 0 | Y19: =TODAY() -> 46104 | AB19: =AA19-Y19 -> -46104
A20: ='MODIFICAR CODIGOS '!A20 -> 0 | B20: ='MODIFICAR CODIGOS '!B20 -> 0 | C20: ='MODIFICAR CODIGOS '!C20 -> 45 | D20: ='MODIFICAR CODIGOS '!D20 -> 9 | E20: ='MODIFICAR CODIGOS '!E20 -> 30 | U20: =(F20*C20+G20*C20+H20*C20+I20*C20+J20*C20+K20*C20+L20*D20+M20*D20+N20*D20+O20*D20+P20*1+Q20*1+R20*1+(TRUNC((S20+T20)/E20)))+(((S20+T20)/E20-TRUNC((S20+T20)/E20))*E20)/100 -> 0 | V20: =(F20*C20+G20*C20+H20*C20+I20*C20+J20*C20+K20*C20+L20*D20+M20*D20+N20*D20+O20*D20+P20*1+Q20*1+R20*1+(TRUNC((S20+T20)/E20))) -> 0 | W20: =(((S20+T20)/E20-TRUNC((S20+T20)/E20))*E20) -> 0 | X20: =V20+W20/E20 -> 0 | Y20: =TODAY() -> 46104 | AB20: =AA20-Y20 -> -46104
A21: ='MODIFICAR CODIGOS '!A21 -> 0 | B21: ='MODIFICAR CODIGOS '!B21 -> 0 | C21: ='MODIFICAR CODIGOS '!C21 -> 45 | D21: ='MODIFICAR CODIGOS '!D21 -> 9 | E21: ='MODIFICAR CODIGOS '!E21 -> 30 | U21: =(F21*C21+G21*C21+H21*C21+I21*C21+J21*C21+K21*C21+L21*D21+M21*D21+N21*D21+O21*D21+P21*1+Q21*1+R21*1+(TRUNC((S21+T21)/E21)))+(((S21+T21)/E21-TRUNC((S21+T21)/E21))*E21)/100 -> 0 | V21: =(F21*C21+G21*C21+H21*C21+I21*C21+J21*C21+K21*C21+L21*D21+M21*D21+N21*D21+O21*D21+P21*1+Q21*1+R21*1+(TRUNC((S21+T21)/E21))) -> 0 | W21: =(((S21+T21)/E21-TRUNC((S21+T21)/E21))*E21) -> 0 | X21: =V21+W21/E21 -> 0 | Y21: =TODAY() -> 46104 | AB21: =AA21-Y21 -> -46104
A22: ='MODIFICAR CODIGOS '!A22 -> 0 | B22: ='MODIFICAR CODIGOS '!B22 -> 0 | C22: ='MODIFICAR CODIGOS '!C22 -> 45 | D22: ='MODIFICAR CODIGOS '!D22 -> 9 | E22: ='MODIFICAR CODIGOS '!E22 -> 30 | U22: =(F22*C22+G22*C22+H22*C22+I22*C22+J22*C22+K22*C22+L22*D22+M22*D22+N22*D22+O22*D22+P22*1+Q22*1+R22*1+(TRUNC((S22+T22)/E22)))+(((S22+T22)/E22-TRUNC((S22+T22)/E22))*E22)/100 -> 0 | V22: =(F22*C22+G22*C22+H22*C22+I22*C22+J22*C22+K22*C22+L22*D22+M22*D22+N22*D22+O22*D22+P22*1+Q22*1+R22*1+(TRUNC((S22+T22)/E22))) -> 0 | W22: =(((S22+T22)/E22-TRUNC((S22+T22)/E22))*E22) -> 0 | X22: =V22+W22/E22 -> 0 | Y22: =TODAY() -> 46104 | AB22: =AA22-Y22 -> -46104
A23: ='MODIFICAR CODIGOS '!A23 -> 0 | B23: ='MODIFICAR CODIGOS '!B23 -> 0 | C23: ='MODIFICAR CODIGOS '!C23 -> 45 | D23: ='MODIFICAR CODIGOS '!D23 -> 9 | E23: ='MODIFICAR CODIGOS '!E23 -> 30 | U23: =(F23*C23+G23*C23+H23*C23+I23*C23+J23*C23+K23*C23+L23*D23+M23*D23+N23*D23+O23*D23+P23*1+Q23*1+R23*1+(TRUNC((S23+T23)/E23)))+(((S23+T23)/E23-TRUNC((S23+T23)/E23))*E23)/100 -> 0 | V23: =(F23*C23+G23*C23+H23*C23+I23*C23+J23*C23+K23*C23+L23*D23+M23*D23+N23*D23+O23*D23+P23*1+Q23*1+R23*1+(TRUNC((S23+T23)/E23))) -> 0 | W23: =(((S23+T23)/E23-TRUNC((S23+T23)/E23))*E23) -> 0 | X23: =V23+W23/E23 -> 0 | Y23: =TODAY() -> 46104 | AB23: =AA23-Y23 -> -46104
A24: ='MODIFICAR CODIGOS '!A24 -> 135666 | B24: ='MODIFICAR CODIGOS '!B24 -> COCA COLA 1.25LT VIR(12) | C24: ='MODIFICAR CODIGOS '!C24 -> 40 | D24: ='MODIFICAR CODIGOS '!D24 -> 10 | E24: ='MODIFICAR CODIGOS '!E24 -> 12 | I24: 1 | Q24: 8 | U24: =(F24*C24+G24*C24+H24*C24+I24*C24+J24*C24+K24*C24+L24*D24+M24*D24+N24*D24+O24*D24+P24*1+Q24*1+R24*1+(TRUNC((S24+T24)/E24)))+(((S24+T24)/E24-TRUNC((S24+T24)/E24))*E24)/100 -> 48 | V24: =(F24*C24+G24*C24+H24*C24+I24*C24+J24*C24+K24*C24+L24*D24+M24*D24+N24*D24+O24*D24+P24*1+Q24*1+R24*1+(TRUNC((S24+T24)/E24))) -> 48 | W24: =(((S24+T24)/E24-TRUNC((S24+T24)/E24))*E24) -> 0 | X24: =V24+W24/E24 -> 48 | Y24: =TODAY() -> 46104 | AB24: =AA24-Y24 -> -46104
A25: ='MODIFICAR CODIGOS '!A25 -> 0 | B25: ='MODIFICAR CODIGOS '!B25 -> 0 | C25: ='MODIFICAR CODIGOS '!C25 -> 40 | D25: ='MODIFICAR CODIGOS '!D25 -> 10 | E25: ='MODIFICAR CODIGOS '!E25 -> 12 | U25: =(F25*C25+G25*C25+H25*C25+I25*C25+J25*C25+K25*C25+L25*D25+M25*D25+N25*D25+O25*D25+P25*1+Q25*1+R25*1+(TRUNC((S25+T25)/E25)))+(((S25+T25)/E25-TRUNC((S25+T25)/E25))*E25)/100 -> 0 | V25: =(F25*C25+G25*C25+H25*C25+I25*C25+J25*C25+K25*C25+L25*D25+M25*D25+N25*D25+O25*D25+P25*1+Q25*1+R25*1+(TRUNC((S25+T25)/E25))) -> 0 | W25: =(((S25+T25)/E25-TRUNC((S25+T25)/E25))*E25) -> 0 | X25: =V25+W25/E25 -> 0 | Y25: =TODAY() -> 46104 | AB25: =AA25-Y25 -> -46104
A26: * | V26: =(F26*C26+G26*C26+H26*C26+I26*C26+J26*C26+K26*C26+L26*D26+M26*D26+N26*D26+O26*D26+P26*1+Q26*1+R26*1+(TRUNC((S26+T26)/E26))) -> #DIV/0! | W26: =(((S26+T26)/E26-TRUNC((S26+T26)/E26))*E26) -> #DIV/0! | AB26: =AA26-Y26 -> 0
A27: ='MODIFICAR CODIGOS '!A27 -> 136159 | B27: ='MODIFICAR CODIGOS '!B27 -> COCA-COLA SO 1 LT NR (12) | C27: ='MODIFICAR CODIGOS '!C27 -> 75 | D27: ='MODIFICAR CODIGOS '!D27 -> 15 | E27: ='MODIFICAR CODIGOS '!E27 -> 12 | I27: 1 | Q27: 62 | U27: =(F27*C27+G27*C27+H27*C27+I27*C27+J27*C27+K27*C27+L27*D27+M27*D27+N27*D27+O27*D27+P27*1+Q27*1+R27*1+(TRUNC((S27+T27)/E27)))+(((S27+T27)/E27-TRUNC((S27+T27)/E27))*E27)/100 -> 137 | V27: =(F27*C27+G27*C27+H27*C27+I27*C27+J27*C27+K27*C27+L27*D27+M27*D27+N27*D27+O27*D27+P27*1+Q27*1+R27*1+(TRUNC((S27+T27)/E27))) -> 137 | W27: =(((S27+T27)/E27-TRUNC((S27+T27)/E27))*E27) -> 0 | X27: =V27+W27/E27 -> 137 | Y27: =TODAY() -> 46104 | AB27: =AA27-Y27 -> -46104
A28: ='MODIFICAR CODIGOS '!A28 -> 136113 | B28: ='MODIFICAR CODIGOS '!B28 -> ESPEJO CCSO 1.5LT PET(12) | C28: ='MODIFICAR CODIGOS '!C28 -> 65 | D28: ='MODIFICAR CODIGOS '!D28 -> 13 | E28: ='MODIFICAR CODIGOS '!E28 -> 12 | H28: 6 | O28: 3 | Q28: 4 | U28: =(F28*C28+G28*C28+H28*C28+I28*C28+J28*C28+K28*C28+L28*D28+M28*D28+N28*D28+O28*D28+P28*1+Q28*1+R28*1+(TRUNC((S28+T28)/E28)))+(((S28+T28)/E28-TRUNC((S28+T28)/E28))*E28)/100 -> 433 | V28: =(F28*C28+G28*C28+H28*C28+I28*C28+J28*C28+K28*C28+L28*D28+M28*D28+N28*D28+O28*D28+P28*1+Q28*1+R28*1+(TRUNC((S28+T28)/E28))) -> 433 | W28: =(((S28+T28)/E28-TRUNC((S28+T28)/E28))*E28) -> 0 | X28: =V28+W28/E28 -> 433 | Y28: =TODAY() -> 46104 | AB28: =AA28-Y28 -> -46104
A29: ='MODIFICAR CODIGOS '!A29 -> 135664 | B29: ='MODIFICAR CODIGOS '!B29 -> COCA-COLA 1.5 LT NR (12) Nvo | C29: ='MODIFICAR CODIGOS '!C29 -> 65 | D29: ='MODIFICAR CODIGOS '!D29 -> 13 | E29: ='MODIFICAR CODIGOS '!E29 -> 12 | Q29: 19 | S29: 10 | U29: =(F29*C29+G29*C29+H29*C29+I29*C29+J29*C29+K29*C29+L29*D29+M29*D29+N29*D29+O29*D29+P29*1+Q29*1+R29*1+(TRUNC((S29+T29)/E29)))+(((S29+T29)/E29-TRUNC((S29+T29)/E29))*E29)/100 -> 19.1 | V29: =(F29*C29+G29*C29+H29*C29+I29*C29+J29*C29+K29*C29+L29*D29+M29*D29+N29*D29+O29*D29+P29*1+Q29*1+R29*1+(TRUNC((S29+T29)/E29))) -> 19 | W29: =(((S29+T29)/E29-TRUNC((S29+T29)/E29))*E29) -> 10 | X29: =V29+W29/E29 -> 19.833333 | Y29: =TODAY() -> 46104 | AB29: =AA29-Y29 -> -46104
A30: ='MODIFICAR CODIGOS '!A30 -> 135757 | B30: ='MODIFICAR CODIGOS '!B30 -> COCA COLA ZERO 1,5 NR (12) | C30: ='MODIFICAR CODIGOS '!C30 -> 65 | D30: ='MODIFICAR CODIGOS '!D30 -> 13 | E30: ='MODIFICAR CODIGOS '!E30 -> 12 | Q30: 8 | S30: 10 | U30: =(F30*C30+G30*C30+H30*C30+I30*C30+J30*C30+K30*C30+L30*D30+M30*D30+N30*D30+O30*D30+P30*1+Q30*1+R30*1+(TRUNC((S30+T30)/E30)))+(((S30+T30)/E30-TRUNC((S30+T30)/E30))*E30)/100 -> 8.1 | V30: =(F30*C30+G30*C30+H30*C30+I30*C30+J30*C30+K30*C30+L30*D30+M30*D30+N30*D30+O30*D30+P30*1+Q30*1+R30*1+(TRUNC((S30+T30)/E30))) -> 8 | W30: =(((S30+T30)/E30-TRUNC((S30+T30)/E30))*E30) -> 10 | X30: =V30+W30/E30 -> 8.8333333 | Y30: =TODAY() -> 46104 | AB30: =AA30-Y30 -> -46104
A31: ='MODIFICAR CODIGOS '!A31 -> 56651 | B31: ='MODIFICAR CODIGOS '!B31 -> PREMIO ROJO 1.5 L | C31: ='MODIFICAR CODIGOS '!C31 -> 65 | D31: ='MODIFICAR CODIGOS '!D31 -> 13 | E31: ='MODIFICAR CODIGOS '!E31 -> 12 | H31: 2 | U31: =(F31*C31+G31*C31+H31*C31+I31*C31+J31*C31+K31*C31+L31*D31+M31*D31+N31*D31+O31*D31+P31*1+Q31*1+R31*1+(TRUNC((S31+T31)/E31)))+(((S31+T31)/E31-TRUNC((S31+T31)/E31))*E31)/100 -> 130 | V31: =(F31*C31+G31*C31+H31*C31+I31*C31+J31*C31+K31*C31+L31*D31+M31*D31+N31*D31+O31*D31+P31*1+Q31*1+R31*1+(TRUNC((S31+T31)/E31))) -> 130 | W31: =(((S31+T31)/E31-TRUNC((S31+T31)/E31))*E31) -> 0 | X31: =V31+W31/E31 -> 130 | Y31: =TODAY() -> 46104 | AB31: =AA31-Y31 -> -46104
A32: ='MODIFICAR CODIGOS '!A32 -> 56709 | B32: ='MODIFICAR CODIGOS '!B32 -> QUATRO 1,5LT | C32: ='MODIFICAR CODIGOS '!C32 -> 65 | D32: ='MODIFICAR CODIGOS '!D32 -> 13 | E32: ='MODIFICAR CODIGOS '!E32 -> 12 | H32: 5 | O32: 3 | P32: 3 | S32: 4 | U32: =(F32*C32+G32*C32+H32*C32+I32*C32+J32*C32+K32*C32+L32*D32+M32*D32+N32*D32+O32*D32+P32*1+Q32*1+R32*1+(TRUNC((S32+T32)/E32)))+(((S32+T32)/E32-TRUNC((S32+T32)/E32))*E32)/100 -> 367.04 | V32: =(F32*C32+G32*C32+H32*C32+I32*C32+J32*C32+K32*C32+L32*D32+M32*D32+N32*D32+O32*D32+P32*1+Q32*1+R32*1+(TRUNC((S32+T32)/E32))) -> 367 | W32: =(((S32+T32)/E32-TRUNC((S32+T32)/E32))*E32) -> 4 | X32: =V32+W32/E32 -> 367.33333 | Y32: =TODAY() -> 46104 | AB32: =AA32-Y32 -> -46104
A33: ='MODIFICAR CODIGOS '!A33 -> 160102 | B33: ='MODIFICAR CODIGOS '!B33 -> SRITE LIMA LIMON 1,5LT | C33: ='MODIFICAR CODIGOS '!C33 -> 65 | D33: ='MODIFICAR CODIGOS '!D33 -> 13 | E33: ='MODIFICAR CODIGOS '!E33 -> 12 | O33: 4 | Q33: 6 | S33: 3 | U33: =(F33*C33+G33*C33+H33*C33+I33*C33+J33*C33+K33*C33+L33*D33+M33*D33+N33*D33+O33*D33+P33*1+Q33*1+R33*1+(TRUNC((S33+T33)/E33)))+(((S33+T33)/E33-TRUNC((S33+T33)/E33))*E33)/100 -> 58.03 | V33: =(F33*C33+G33*C33+H33*C33+I33*C33+J33*C33+K33*C33+L33*D33+M33*D33+N33*D33+O33*D33+P33*1+Q33*1+R33*1+(TRUNC((S33+T33)/E33))) -> 58 | W33: =(((S33+T33)/E33-TRUNC((S33+T33)/E33))*E33) -> 3 | X33: =V33+W33/E33 -> 58.25 | Y33: =TODAY() -> 46104 | AB33: =AA33-Y33 -> -46104
A34: ='MODIFICAR CODIGOS '!A34 -> 160100 | B34: ='MODIFICAR CODIGOS '!B34 -> SCHEPPES GINGER 1,5 LTS | C34: ='MODIFICAR CODIGOS '!C34 -> 65 | D34: ='MODIFICAR CODIGOS '!D34 -> 13 | E34: ='MODIFICAR CODIGOS '!E34 -> 12 | Q34: 6 | S34: 1 | U34: =(F34*C34+G34*C34+H34*C34+I34*C34+J34*C34+K34*C34+L34*D34+M34*D34+N34*D34+O34*D34+P34*1+Q34*1+R34*1+(TRUNC((S34+T34)/E34)))+(((S34+T34)/E34-TRUNC((S34+T34)/E34))*E34)/100 -> 6.01 | V34: =(F34*C34+G34*C34+H34*C34+I34*C34+J34*C34+K34*C34+L34*D34+M34*D34+N34*D34+O34*D34+P34*1+Q34*1+R34*1+(TRUNC((S34+T34)/E34))) -> 6 | W34: =(((S34+T34)/E34-TRUNC((S34+T34)/E34))*E34) -> 1 | X34: =V34+W34/E34 -> 6.0833333 | Y34: =TODAY() -> 46104 | AB34: =AA34-Y34 -> -46104
A35: ='MODIFICAR CODIGOS '!A35 -> 160101 | B35: ='MODIFICAR CODIGOS '!B35 -> SCHEPPES SODA 1,5 LTS | C35: ='MODIFICAR CODIGOS '!C35 -> 65 | D35: ='MODIFICAR CODIGOS '!D35 -> 13 | E35: ='MODIFICAR CODIGOS '!E35 -> 12 | O35: 2 | P35: 9 | S35: 2 | U35: =(F35*C35+G35*C35+H35*C35+I35*C35+J35*C35+K35*C35+L35*D35+M35*D35+N35*D35+O35*D35+P35*1+Q35*1+R35*1+(TRUNC((S35+T35)/E35)))+(((S35+T35)/E35-TRUNC((S35+T35)/E35))*E35)/100 -> 35.02 | V35: =(F35*C35+G35*C35+H35*C35+I35*C35+J35*C35+K35*C35+L35*D35+M35*D35+N35*D35+O35*D35+P35*1+Q35*1+R35*1+(TRUNC((S35+T35)/E35))) -> 35 | W35: =(((S35+T35)/E35-TRUNC((S35+T35)/E35))*E35) -> 2 | X35: =V35+W35/E35 -> 35.166667 | Y35: =TODAY() -> 46104 | AB35: =AA35-Y35 -> -46104
A36: ='MODIFICAR CODIGOS '!A36 -> 160099 | B36: ='MODIFICAR CODIGOS '!B36 -> KOLA ROMA 1,5 LTS | C36: ='MODIFICAR CODIGOS '!C36 -> 65 | D36: ='MODIFICAR CODIGOS '!D36 -> 13 | E36: ='MODIFICAR CODIGOS '!E36 -> 12 | Q36: 3 | S36: 2 | U36: =(F36*C36+G36*C36+H36*C36+I36*C36+J36*C36+K36*C36+L36*D36+M36*D36+N36*D36+O36*D36+P36*1+Q36*1+R36*1+(TRUNC((S36+T36)/E36)))+(((S36+T36)/E36-TRUNC((S36+T36)/E36))*E36)/100 -> 3.02 | V36: =(F36*C36+G36*C36+H36*C36+I36*C36+J36*C36+K36*C36+L36*D36+M36*D36+N36*D36+O36*D36+P36*1+Q36*1+R36*1+(TRUNC((S36+T36)/E36))) -> 3 | W36: =(((S36+T36)/E36-TRUNC((S36+T36)/E36))*E36) -> 2 | X36: =V36+W36/E36 -> 3.1666667 | Y36: =TODAY() -> 46104 | AB36: =AA36-Y36 -> -46104
A37: * | V37: =(F37*C37+G37*C37+H37*C37+I37*C37+J37*C37+K37*C37+L37*D37+M37*D37+N37*D37+O37*D37+P37*1+Q37*1+R37*1+(TRUNC((S37+T37)/E37))) -> #DIV/0! | W37: =(((S37+T37)/E37-TRUNC((S37+T37)/E37))*E37) -> #DIV/0! | AB37: =AA37-Y37 -> 0
A38: ='MODIFICAR CODIGOS '!A38 -> 0 | B38: ='MODIFICAR CODIGOS '!B38 -> 0 | C38: ='MODIFICAR CODIGOS '!C38 -> 0 | D38: ='MODIFICAR CODIGOS '!D38 -> 0 | E38: ='MODIFICAR CODIGOS '!E38 -> 1 | U38: =(F38*C38+G38*C38+H38*C38+I38*C38+J38*C38+K38*C38+L38*D38+M38*D38+N38*D38+O38*D38+P38*1+Q38*1+R38*1+(TRUNC((S38+T38)/E38)))+(((S38+T38)/E38-TRUNC((S38+T38)/E38))*E38)/100 -> 0 | V38: =(F38*C38+G38*C38+H38*C38+I38*C38+J38*C38+K38*C38+L38*D38+M38*D38+N38*D38+O38*D38+P38*1+Q38*1+R38*1+(TRUNC((S38+T38)/E38))) -> 0 | W38: =(((S38+T38)/E38-TRUNC((S38+T38)/E38))*E38) -> 0 | X38: =V38+W38/E38 -> 0 | Y38: =TODAY() -> 46104 | AB38: =AA38-Y38 -> -46104
A39: ='MODIFICAR CODIGOS '!A39 -> 136133 | B39: ='MODIFICAR CODIGOS '!B39 -> COCA COLA 2.25L PET(8) EINSTEIN | C39: ='MODIFICAR CODIGOS '!C39 -> 60 | D39: ='MODIFICAR CODIGOS '!D39 -> 12 | E39: ='MODIFICAR CODIGOS '!E39 -> 8 | H39: 2 | Q39: 7 | S39: 1 | U39: =(F39*C39+G39*C39+H39*C39+I39*C39+J39*C39+K39*C39+L39*D39+M39*D39+N39*D39+O39*D39+P39*1+Q39*1+R39*1+(TRUNC((S39+T39)/E39)))+(((S39+T39)/E39-TRUNC((S39+T39)/E39))*E39)/100 -> 127.01 | V39: =(F39*C39+G39*C39+H39*C39+I39*C39+J39*C39+K39*C39+L39*D39+M39*D39+N39*D39+O39*D39+P39*1+Q39*1+R39*1+(TRUNC((S39+T39)/E39))) -> 127 | W39: =(((S39+T39)/E39-TRUNC((S39+T39)/E39))*E39) -> 1 | X39: =V39+W39/E39 -> 127.125 | Y39: =TODAY() -> 46104 | AB39: =AA39-Y39 -> -46104
A40: ='MODIFICAR CODIGOS '!A40 -> 0 | B40: ='MODIFICAR CODIGOS '!B40 -> 0 | C40: ='MODIFICAR CODIGOS '!C40 -> 0 | D40: ='MODIFICAR CODIGOS '!D40 -> 0 | E40: ='MODIFICAR CODIGOS '!E40 -> 1 | U40: =(F40*C40+G40*C40+H40*C40+I40*C40+J40*C40+K40*C40+L40*D40+M40*D40+N40*D40+O40*D40+P40*1+Q40*1+R40*1+(TRUNC((S40+T40)/E40)))+(((S40+T40)/E40-TRUNC((S40+T40)/E40))*E40)/100 -> 0 | V40: =(F40*C40+G40*C40+H40*C40+I40*C40+J40*C40+K40*C40+L40*D40+M40*D40+N40*D40+O40*D40+P40*1+Q40*1+R40*1+(TRUNC((S40+T40)/E40))) -> 0 | W40: =(((S40+T40)/E40-TRUNC((S40+T40)/E40))*E40) -> 0 | X40: =V40+W40/E40 -> 0 | Y40: =TODAY() -> 46104 | AB40: =AA40-Y40 -> -46104
...

Sheet INVENTARIO PISO 
A2: INVENTARIO PISO
D3: INV PISO =
B4: Fecha: | C4: 43165 | D4: FILTRAR
A5: Producto | B5: Descripción | C5: und | D5: Cantidad | F5: cantidades | G5: UND | H5: conversion | I5: cantidad
A6: ='PLANTILLA INV. PISO (0)'!A2 -> 160052 | B6: ='PLANTILLA INV. PISO (0)'!B2 -> COCA-COLA 6,5OZ VIR(30) | C6: ='MODIFICAR CODIGOS '!E2 -> 30 | D6: ='PLANTILLA INV. PISO (0)'!U2 -> 99.05 | F6: =ROUNDDOWN(D6,0) -> 99 | G6: =+(D6-F6)*100 -> 5 | H6: =G6/C6 -> 0.16666667 | I6: =F6+H6 -> 99.166667 | K6: ='PLANTILLA INV. PISO (0)'!AA2 -> 46178
A7: ='PLANTILLA INV. PISO (0)'!A3 -> 0 | B7: ='PLANTILLA INV. PISO (0)'!B3 -> 0 | C7: ='MODIFICAR CODIGOS '!E3 -> 30 | D7: ='PLANTILLA INV. PISO (0)'!U3 -> 0 | F7: =ROUNDDOWN(D7,0) -> 0 | G7: =+(D7-F7)*100 -> 0 | H7: =G7/C7 -> 0 | I7: =F7+H7 -> 0 | K7: ='PLANTILLA INV. PISO (0)'!AA3 -> 0
A8: ='PLANTILLA INV. PISO (0)'!A4 -> 56702 | B8: ='PLANTILLA INV. PISO (0)'!B4 -> QUATRO TJA 6,5OZ VIR(30) | C8: ='MODIFICAR CODIGOS '!E4 -> 30 | D8: ='PLANTILLA INV. PISO (0)'!U4 -> 58.21 | F8: =ROUNDDOWN(D8,0) -> 58 | G8: =+(D8-F8)*100 -> 21 | H8: =G8/C8 -> 0.7 | I8: =F8+H8 -> 58.7 | K8: ='PLANTILLA INV. PISO (0)'!AA4 -> 0
A9: ='PLANTILLA INV. PISO (0)'!A5 -> 0 | B9: ='PLANTILLA INV. PISO (0)'!B5 -> 0 | C9: ='MODIFICAR CODIGOS '!E5 -> 30 | D9: ='PLANTILLA INV. PISO (0)'!U5 -> 0 | F9: =ROUNDDOWN(D9,0) -> 0 | G9: =+(D9-F9)*100 -> 0 | H9: =G9/C9 -> 0 | I9: =F9+H9 -> 0 | K9: ='PLANTILLA INV. PISO (0)'!AA5 -> 0
A10: ='PLANTILLA INV. PISO (0)'!A6 -> 160069 | B10: ='PLANTILLA INV. PISO (0)'!B6 -> SPRITE LL6,5 OZ | C10: ='MODIFICAR CODIGOS '!E6 -> 30 | D10: ='PLANTILLA INV. PISO (0)'!U6 -> 97.08 | F10: =ROUNDDOWN(D10,0) -> 97 | G10: =+(D10-F10)*100 -> 8 | H10: =G10/C10 -> 0.26666667 | I10: =F10+H10 -> 97.266667 | K10: ='PLANTILLA INV. PISO (0)'!AA6 -> 0
A11: ='PLANTILLA INV. PISO (0)'!A7 -> 0 | B11: ='PLANTILLA INV. PISO (0)'!B7 -> 0 | C11: ='MODIFICAR CODIGOS '!E7 -> 30 | D11: ='PLANTILLA INV. PISO (0)'!U7 -> 0 | F11: =ROUNDDOWN(D11,0) -> 0 | G11: =+(D11-F11)*100 -> 0 | H11: =G11/C11 -> 0 | I11: =F11+H11 -> 0 | K11: ='PLANTILLA INV. PISO (0)'!AA7 -> 0
A12: ='PLANTILLA INV. PISO (0)'!A8 -> 0 | B12: ='PLANTILLA INV. PISO (0)'!B8 -> 0 | C12: ='MODIFICAR CODIGOS '!E8 -> 30 | D12: ='PLANTILLA INV. PISO (0)'!U8 -> 0 | F12: =ROUNDDOWN(D12,0) -> 0 | G12: =+(D12-F12)*100 -> 0 | H12: =G12/C12 -> 0 | I12: =F12+H12 -> 0 | K12: ='PLANTILLA INV. PISO (0)'!AA8 -> 0
A13: ='PLANTILLA INV. PISO (0)'!A9 -> 0 | B13: ='PLANTILLA INV. PISO (0)'!B9 -> 0 | C13: ='MODIFICAR CODIGOS '!E9 -> 30 | D13: ='PLANTILLA INV. PISO (0)'!U9 -> 0 | F13: =ROUNDDOWN(D13,0) -> 0 | G13: =+(D13-F13)*100 -> 0 | H13: =G13/C13 -> 0 | I13: =F13+H13 -> 0 | K13: ='PLANTILLA INV. PISO (0)'!AA9 -> 0
A14: ='PLANTILLA INV. PISO (0)'!A10 -> 56623 | B14: ='PLANTILLA INV. PISO (0)'!B10 -> PREMIO ROJO 250 ML RGB | C14: ='MODIFICAR CODIGOS '!E10 -> 30 | D14: ='PLANTILLA INV. PISO (0)'!U10 -> 0 | F14: =ROUNDDOWN(D14,0) -> 0 | G14: =+(D14-F14)*100 -> 0 | H14: =G14/C14 -> 0 | I14: =F14+H14 -> 0 | K14: ='PLANTILLA INV. PISO (0)'!AA10 -> 0
A15: ='PLANTILLA INV. PISO (0)'!A11 -> * | B15: ='PLANTILLA INV. PISO (0)'!B11 -> 0 | C15: ='MODIFICAR CODIGOS '!E11 -> 0 | D15: ='PLANTILLA INV. PISO (0)'!U11 -> 0 | F15: =ROUNDDOWN(D15,0) -> 0 | G15: =+(D15-F15)*100 -> 0 | H15: =G15/C15 -> #DIV/0! | I15: =F15+H15 -> #DIV/0! | K15: ='PLANTILLA INV. PISO (0)'!AA11 -> 0
A16: ='PLANTILLA INV. PISO (0)'!A12 -> 160053 | B16: ='PLANTILLA INV. PISO (0)'!B12 -> COCA-COLA 350ML VIR(30) | C16: ='MODIFICAR CODIGOS '!E12 -> 30 | D16: ='PLANTILLA INV. PISO (0)'!U12 -> 42.1 | F16: =ROUNDDOWN(D16,0) -> 42 | G16: =+(D16-F16)*100 -> 10 | H16: =G16/C16 -> 0.33333333 | I16: =F16+H16 -> 42.333333 | K16: ='PLANTILLA INV. PISO (0)'!AA12 -> 0
A17: ='PLANTILLA INV. PISO (0)'!A13 -> 135763 | B17: ='PLANTILLA INV. PISO (0)'!B13 -> COCA COLA ZERO 350 ML VIR | C17: ='MODIFICAR CODIGOS '!E13 -> 30 | D17: ='PLANTILLA INV. PISO (0)'!U13 -> 18.24 | F17: =ROUNDDOWN(D17,0) -> 18 | G17: =+(D17-F17)*100 -> 24 | H17: =G17/C17 -> 0.8 | I17: =F17+H17 -> 18.8 | K17: ='PLANTILLA INV. PISO (0)'!AA13 -> 0
... A31: ='PLANTILLA INV. PISO (0)'!A27 -> 136159 | B31: ='PLANTILLA INV. PISO (0)'!B27 -> COCA-COLA SO 1 LT NR (12) | C31: ='MODIFICAR CODIGOS '!E27 -> 12 | D31: ='PLANTILLA INV. PISO (0)'!U27 -> 137 | F31: =ROUNDDOWN(D31,0) -> 137 | G31: =+(D31-F31)*100 -> 0 | H31: =G31/C31 -> 0 | I31: =F31+H31 -> 137 | K31: ='PLANTILLA INV. PISO (0)'!AA27 -> 0
A32: ='PLANTILLA INV. PISO (0)'!A28 -> 136113 | B32: ='PLANTILLA INV. PISO (0)'!B28 -> ESPEJO CCSO 1.5LT PET(12) | C32: ='MODIFICAR CODIGOS '!E28 -> 12 | D32: ='PLANTILLA INV. PISO (0)'!U28 -> 433 | F32: =ROUNDDOWN(D32,0) -> 433 | G32: =+(D32-F32)*100 -> 0 | H32: =G32/C32 -> 0 | I32: =F32+H32 -> 433
A33: ='PLANTILLA INV. PISO (0)'!A29 -> 135664 | B33: ='PLANTILLA INV. PISO (0)'!B29 -> COCA-COLA 1.5 LT NR (12) Nvo | C33: ='MODIFICAR CODIGOS '!E29 -> 12 | D33: ='PLANTILLA INV. PISO (0)'!U29 -> 19.1 | F33: =ROUNDDOWN(D33,0) -> 19 | G33: =+(D33-F33)*100 -> 10 | H33: =G33/C33 -> 0.83333333 | I33: =F33+H33 -> 19.833333 | K33: ='PLANTILLA INV. PISO (0)'!AA29 -> 0
A34: ='PLANTILLA INV. PISO (0)'!A30 -> 135757 | B34: ='PLANTILLA INV. PISO (0)'!B30 -> COCA COLA ZERO 1,5 NR (12) | C34: ='MODIFICAR CODIGOS '!E30 -> 12 | D34: ='PLANTILLA INV. PISO (0)'!U30 -> 8.1 | F34: =ROUNDDOWN(D34,0) -> 8 | G34: =+(D34-F34)*100 -> 10 | H34: =G34/C34 -> 0.83333333 | I34: =F34+H34 -> 8.8333333 | K34: ='PLANTILLA INV. PISO (0)'!AA30 -> 0
A35: ='PLANTILLA INV. PISO (0)'!A31 -> 56651 | B35: ='PLANTILLA INV. PISO (0)'!B31 -> PREMIO ROJO 1.5 L | C35: ='MODIFICAR CODIGOS '!E31 -> 12 | D35: ='PLANTILLA INV. PISO (0)'!U31 -> 130 | F35: =ROUNDDOWN(D35,0) -> 130 | G35: =+(D35-F35)*100 -> 0 | H35: =G35/C35 -> 0 | I35: =F35+H35 -> 130 | K35: ='PLANTILLA INV. PISO (0)'!AA31 -> 0
A36: ='PLANTILLA INV. PISO (0)'!A32 -> 56709 | B36: ='PLANTILLA INV. PISO (0)'!B32 -> QUATRO 1,5LT | C36: ='MODIFICAR CODIGOS '!E32 -> 12 | D36: ='PLANTILLA INV. PISO (0)'!U32 -> 367.04 | F36: =ROUNDDOWN(D36,0) -> 367 | G36: =+(D36-F36)*100 -> 4 | H36: =G36/C36 -> 0.33333333 | I36: =F36+H36 -> 367.33333 | K36: ='PLANTILLA INV. PISO (0)'!AA32 -> 0
A37: ='PLANTILLA INV. PISO (0)'!A33 -> 160102 | B37: ='PLANTILLA INV. PISO (0)'!B33 -> SRITE LIMA LIMON 1,5LT | C37: ='MODIFICAR CODIGOS '!E33 -> 12 | D37: ='PLANTILLA INV. PISO (0)'!U33 -> 58.03 | F37: =ROUNDDOWN(D37,0) -> 58 | G37: =+(D37-F37)*100 -> 3 | H37: =G37/C37 -> 0.25 | I37: =F37+H37 -> 58.25 | K37: ='PLANTILLA INV. PISO (0)'!AA33 -> 0
A38: ='PLANTILLA INV. PISO (0)'!A34 -> 160100 | B38: ='PLANTILLA INV. PISO (0)'!B34 -> SCHEPPES GINGER 1,5 LTS | C38: ='MODIFICAR CODIGOS '!E34 -> 12 | D38: ='PLANTILLA INV. PISO (0)'!U34 -> 6.01 | F38: =ROUNDDOWN(D38,0) -> 6 | G38: =+(D38-F38)*100 -> 1 | H38: =G38/C38 -> 0.083333333 | I38: =F38+H38 -> 6.0833333 | K38: ='PLANTILLA INV. PISO (0)'!AA34 -> 0
A39: ='PLANTILLA INV. PISO (0)'!A35 -> 160101 | B39: ='PLANTILLA INV. PISO (0)'!B35 -> SCHEPPES SODA 1,5 LTS | C39: ='MODIFICAR CODIGOS '!E35 -> 12 | D39: ='PLANTILLA INV. PISO (0)'!U35 -> 35.02 | F39: =ROUNDDOWN(D39,0) -> 35 | G39: =+(D39-F39)*100 -> 2 | H39: =G39/C39 -> 0.16666667 | I39: =F39+H39 -> 35.166667 | K39: ='PLANTILLA INV. PISO (0)'!AA35 -> 0
A40: ='PLANTILLA INV. PISO (0)'!A36 -> 160099 | B40: ='PLANTILLA INV. PISO (0)'!B36 -> KOLA ROMA 1,5 LTS | C40: ='MODIFICAR CODIGOS '!E36 -> 12 | D40: ='PLANTILLA INV. PISO (0)'!U36 -> 3.02 | F40: =ROUNDDOWN(D40,0) -> 3 | G40: =+(D40-F40)*100 -> 2 | H40: =G40/C40 -> 0.16666667 | I40: =F40+H40 -> 3.1666667 | K40: ='PLANTILLA INV. PISO (0)'!AA36 -> 0
A41: ='PLANTILLA INV. PISO (0)'!A37 -> * | B41: ='PLANTILLA INV. PISO (0)'!B37 -> 0 | C41: ='MODIFICAR CODIGOS '!E37 -> 0 | D41: ='PLANTILLA INV. PISO (0)'!U37 -> 0 | F41: =ROUNDDOWN(D41,0) -> 0 | G41: =+(D41-F41)*100 -> 0 | H41: =G41/C41 -> #DIV/0! | I41: =F41+H41 -> #DIV/0! | K41: ='PLANTILLA INV. PISO (0)'!AA37 -> 0
A42: ='PLANTILLA INV. PISO (0)'!A38 -> 0 | B42: ='PLANTILLA INV. PISO (0)'!B38 -> 0 | C42: ='MODIFICAR CODIGOS '!E38 -> 1 | D42: ='PLANTILLA INV. PISO (0)'!U38 -> 0 | F42: =ROUNDDOWN(D42,0) -> 0 | G42: =+(D42-F42)*100 -> 0 | H42: =G42/C42 -> 0 | I42: =F42+H42 -> 0 | K42: ='PLANTILLA INV. PISO (0)'!AA38 -> 0
A43: ='PLANTILLA INV. PISO (0)'!A39 -> 136133 | B43: ='PLANTILLA INV. PISO (0)'!B39 -> COCA COLA 2.25L PET(8) EINSTEIN | C43: ='MODIFICAR CODIGOS '!E39 -> 8 | D43: ='PLANTILLA INV. PISO (0)'!U39 -> 127.01 | F43: =ROUNDDOWN(D43,0) -> 127 | G43: =+(D43-F43)*100 -> 1 | H43: =G43/C43 -> 0.125 | I43: =F43+H43 -> 127.125 | K43: ='PLANTILLA INV. PISO (0)'!AA39 -> 0
A44: ='PLANTILLA INV. PISO (0)'!A40 -> 0 | B44: ='PLANTILLA INV. PISO (0)'!B40 -> 0 | C44: ='MODIFICAR CODIGOS '!E40 -> 1 | D44: ='PLANTILLA INV. PISO (0)'!U40 -> 0 | F44: =ROUNDDOWN(D44,0) -> 0 | G44: =+(D44-F44)*100 -> 0 | H44: =G44/C44 -> 0 | I44: =F44+H44 -> 0 | K44: ='PLANTILLA INV. PISO (0)'!AA40 -> 0
... A80: ='PLANTILLA INV. PISO (0)'!A76 -> 135759 | B80: ='PLANTILLA INV. PISO (0)'!B76 -> COCA-COLA ZERO 20 OZ PET(15) | C80: ='MODIFICAR CODIGOS '!E76 -> 15 | D80: ='PLANTILLA INV. PISO (0)'!U76 -> 21 | F80: =ROUNDDOWN(D80,0) -> 21 | G80: =+(D80-F80)*100 -> 0 | H80: =G80/C80 -> 0 | I80: =F80+H80 -> 21 | K80: ='PLANTILLA INV. PISO (0)'!AA76 -> 0
A81: ='PLANTILLA INV. PISO (0)'!A77 -> 0 | B81: ='PLANTILLA INV. PISO (0)'!B77 -> 0 | C81: ='MODIFICAR CODIGOS '!E77 -> 1 | D81: ='PLANTILLA INV. PISO (0)'!U77 -> 0 | F81: =ROUNDDOWN(D81,0) -> 0 | G81: =+(D81-F81)*100 -> 0 | H81: =G81/C81 -> 0 | I81: =F81+H81 -> 0 | K81: ='PLANTILLA INV. PISO (0)'!AA78 -> 0
A82: ='PLANTILLA INV. PISO (0)'!A78 -> 0 | B82: ='PLANTILLA INV. PISO (0)'!B78 -> 0 | C82: ='MODIFICAR CODIGOS '!E78 -> 1 | D82: ='PLANTILLA INV. PISO (0)'!U78 -> 0 | F82: =ROUNDDOWN(D82,0) -> 0 | G82: =+(D82-F82)*100 -> 0 | H82: =G82/C82 -> 0 | I82: =F82+H82 -> 0 | K82: ='PLANTILLA INV. PISO (0)'!AA79 -> 0
A83: ='PLANTILLA INV. PISO (0)'!A79 -> * | B83: ='PLANTILLA INV. PISO (0)'!B79 -> 0 | C83: ='MODIFICAR CODIGOS '!E79 -> 0 | D83: ='PLANTILLA INV. PISO (0)'!U79 -> 0 | F83: =ROUNDDOWN(D83,0) -> 0 | G83: =+(D83-F83)*100 -> 0 | H83: =G83/C83 -> #DIV/0! | I83: =F83+H83 -> #DIV/0! | K83: ='PLANTILLA INV. PISO (0)'!AA80 -> 0
A84: ='PLANTILLA INV. PISO (0)'!A80 -> 135760 | B84: ='PLANTILLA INV. PISO (0)'!B80 -> COCA COLA SA 400ML | C84: ='MODIFICAR CODIGOS '!E80 -> 12 | D84: ='PLANTILLA INV. PISO (0)'!U80 -> 302.1 | F84: =ROUNDDOWN(D84,0) -> 302 | G84: =+(D84-F84)*100 -> 10 | H84: =G84/C84 -> 0.83333333 | I84: =F84+H84 -> 302.83333 | K84: ='PLANTILLA INV. PISO (0)'!AA81 -> 0
A85: ='PLANTILLA INV. PISO (0)'!A81 -> 160318 | B85: ='PLANTILLA INV. PISO (0)'!B81 -> COCA-COLA 400ml PET(12) | C85: ='MODIFICAR CODIGOS '!E81 -> 12 | D85: ='PLANTILLA INV. PISO (0)'!U81 -> 3111.11 | F85: =ROUNDDOWN(D85,0) -> 3111 | G85: =+(D85-F85)*100 -> 11 | H85: =G85/C85 -> 0.91666667 | I85: =F85+H85 -> 3111.9167 | K85: ='PLANTILLA INV. PISO (0)'!AA82 -> 0
A86: ='PLANTILLA INV. PISO (0)'!A82 -> * | B86: ='PLANTILLA INV. PISO (0)'!B82 -> 0 | C86: ='MODIFICAR CODIGOS '!E82 -> 0 | D86: ='PLANTILLA INV. PISO (0)'!U82 -> 0 | F86: =ROUNDDOWN(D86,0) -> 0 | G86: =+(D86-F86)*100 -> 0 | H86: =G86/C86 -> #DIV/0! | I86: =F86+H86 -> #DIV/0! | K86: ='PLANTILLA INV. PISO (0)'!AA83 -> 0
A87: ='PLANTILLA INV. PISO (0)'!A83 -> 56452 | B87: ='PLANTILLA INV. PISO (0)'!B83 -> SCHWEPPES SODA 400ML PET (12) | C87: ='MODIFICAR CODIGOS '!E83 -> 12 | D87: ='PLANTILLA INV. PISO (0)'!U83 -> 43.07 | F87: =ROUNDDOWN(D87,0) -> 43 | G87: =+(D87-F87)*100 -> 7 | H87: =G87/C87 -> 0.58333333 | I87: =F87+H87 -> 43.583333 | K87: ='PLANTILLA INV. PISO (0)'!AA84 -> 0
A88: ='PLANTILLA INV. PISO (0)'!A84 -> 56453 | B88: ='PLANTILLA INV. PISO (0)'!B84 -> SCHWEPPES GINGER 400ML PET (12) | C88: ='MODIFICAR CODIGOS '!E84 -> 12 | D88: ='PLANTILLA INV. PISO (0)'!U84 -> 0 | F88: =ROUNDDOWN(D88,0) -> 0 | G88: =+(D88-F88)*100 -> 0 | H88: =G88/C88 -> 0 | I88: =F88+H88 -> 0 | K88: ='PLANTILLA INV. PISO (0)'!AA85 -> 0
A89: ='PLANTILLA INV. PISO (0)'!A85 -> 160479 | B89: ='PLANTILLA INV. PISO (0)'!B85 -> KOLA ROMAN 400 ML NR (12) | C89: ='MODIFICAR CODIGOS '!E85 -> 12 | D89: ='PLANTILLA INV. PISO (0)'!U85 -> 8.08 | F89: =ROUNDDOWN(D89,0) -> 8 | G89: =+(D89-F89)*100 -> 8 | H89: =G89/C89 -> 0.66666667 | I89: =F89+H89 -> 8.6666667 | K89: ='PLANTILLA INV. PISO (0)'!AA86 -> 0
...

Sheet CANTIDADES 
B2: SOLO PRODUCTO | E2: SOLO MATERIAL VACIO
B4: Material | C4: Cantidad Cajas | E4: Material | F4: Cantidad Cajas
B5: 160052 | C5: =IFERROR(VLOOKUP(B5,'INVENTARIO PISO '!A$6:K$470,9,FALSE),"0") -> 99.166667 | E5: 184016 | F5: =IFERROR(VLOOKUP(E5,'INVENTARIO PISO '!$A$433:D470,4,FALSE),"0") -> 0
B6: 56702 | C6: =IFERROR(VLOOKUP(B6,'INVENTARIO PISO '!A$6:K$470,9,FALSE),"0") -> 58.7 | E6: 184025 | F6: =IFERROR(VLOOKUP(E6,'INVENTARIO PISO '!$A$433:D471,4,FALSE),"0") -> 142
B7: 160069 | C7: =IFERROR(VLOOKUP(B7,'INVENTARIO PISO '!A$6:K$470,9,FALSE),"0") -> 97.266667 | E7: 184026 | F7: =IFERROR(VLOOKUP(E7,'INVENTARIO PISO '!$A$433:D472,4,FALSE),"0") -> 90
B8: 160176 | C8: =IFERROR(VLOOKUP(B8,'INVENTARIO PISO '!A$6:K$470,9,FALSE),"0") -> 0 | E8: 184040 | F8: =IFERROR(VLOOKUP(E8,'INVENTARIO PISO '!$A$433:D473,4,FALSE),"0") -> 0
B9: 56623 | C9: =IFERROR(VLOOKUP(B9,'INVENTARIO PISO '!A$6:K$470,9,FALSE),"0") -> 0 | E9: 184041 | F9: =IFERROR(VLOOKUP(E9,'INVENTARIO PISO '!$A$433:D474,4,FALSE),"0") -> 1
B10: 160009 | C10: =IFERROR(VLOOKUP(B10,'INVENTARIO PISO '!A$6:K$470,9,FALSE),"0") -> 0 | E10: 184021 | F10: =IFERROR(VLOOKUP(E10,'INVENTARIO PISO '!$A$433:D475,4,FALSE),"0") -> 0
B11: 119945 | C11: =IFERROR(VLOOKUP(B11,'INVENTARIO PISO '!A$6:K$470,9,FALSE),"0") -> 0 | E11: 183131 | F11: =IFERROR(VLOOKUP(E11,'INVENTARIO PISO '!$A$433:D476,4,FALSE),"0") -> 0
B12: 160033 | C12: =IFERROR(VLOOKUP(B12,'INVENTARIO PISO '!A$6:K$470,9,FALSE),"0") -> 3.3 | E12: 184035 | F12: =IFERROR(VLOOKUP(E12,'INVENTARIO PISO '!$A$433:D477,4,FALSE),"0") -> 47
B13: 160053 | C13: =IFERROR(VLOOKUP(B13,'INVENTARIO PISO '!A$6:K$470,9,FALSE),"0") -> 42.333333 | E13: 184017 | F13: =IFERROR(VLOOKUP(E13,'INVENTARIO PISO '!$A$433:D478,4,FALSE),"0") -> 558
B14: 56622 | C14: =IFERROR(VLOOKUP(B14,'INVENTARIO PISO '!A$6:K$470,9,FALSE),"0") -> 35.666667 | E14: 184022 | F14: =IFERROR(VLOOKUP(E14,'INVENTARIO PISO '!$A$433:D479,4,FALSE),"0") -> 51
B15: 56705 | C15: =IFERROR(VLOOKUP(B15,'INVENTARIO PISO '!A$6:K$470,9,FALSE),"0") -> 32.833333 | E15: 184019 | F15: =IFERROR(VLOOKUP(E15,'INVENTARIO PISO '!$A$433:D480,4,FALSE),"0") -> 190
B16: 160070 | C16: =IFERROR(VLOOKUP(B16,'INVENTARIO PISO '!A$6:K$470,9,FALSE),"0") -> 43.833333 | E16: 184020 | F16: =IFERROR(VLOOKUP(E16,'INVENTARIO PISO '!$A$433:D481,4,FALSE),"0") -> 106
... B31: 160255 | C31: =IFERROR(VLOOKUP(B31,'INVENTARIO PISO '!A$6:K$470,9,FALSE),"0") -> 0 | E31: 197826 | F31: =IFERROR(VLOOKUP(E31,'INVENTARIO PISO '!$A$433:D496,4,FALSE),"0") -> 97
E32: 197815 | F32: =IFERROR(VLOOKUP(E32,'INVENTARIO PISO '!$A$433:D497,4,FALSE),"0") -> 448
E33: 197812 | F33: =IFERROR(VLOOKUP(E33,'INVENTARIO PISO '!$A$433:D498,4,FALSE),"0") -> 74
E34: 197823 | F34: =IFERROR(VLOOKUP(E34,'INVENTARIO PISO '!$A$433:D499,4,FALSE),"0") -> 41
E35: 197794 | F35: =IFERROR(VLOOKUP(E35,'INVENTARIO PISO '!$A$433:D500,4,FALSE),"0") -> 45
E36: 197792 | F36: =IFERROR(VLOOKUP(E36,'INVENTARIO PISO '!$A$433:D501,4,FALSE),"0") -> 0
B38: ='INVENTARIO PISO '!A6 -> 160052 | C38: ='INVENTARIO PISO '!I6 -> 99.166667
B39: ='INVENTARIO PISO '!A7 -> 0 | C39: ='INVENTARIO PISO '!I7 -> 0
B40: ='INVENTARIO PISO '!A8 -> 56702 | C40: ='INVENTARIO PISO '!I8 -> 58.7
B41: ='INVENTARIO PISO '!A9 -> 0 | C41: ='INVENTARIO PISO '!I9 -> 0
B42: ='INVENTARIO PISO '!A10 -> 160069 | C42: ='INVENTARIO PISO '!I10 -> 97.266667
B43: ='INVENTARIO PISO '!A11 -> 0 | C43: ='INVENTARIO PISO '!I11 -> 0
B44: ='INVENTARIO PISO '!A12 -> 0 | C44: ='INVENTARIO PISO '!I12 -> 0
B45: ='INVENTARIO PISO '!A13 -> 0 | C45: ='INVENTARIO PISO '!I13 -> 0
B46: ='INVENTARIO PISO '!A14 -> 56623 | C46: ='INVENTARIO PISO '!I14 -> 0
B47: ='INVENTARIO PISO '!A15 -> * | C47: ='INVENTARIO PISO '!I15 -> #DIV/0!
B48: ='INVENTARIO PISO '!A16 -> 160053 | C48: ='INVENTARIO PISO '!I16 -> 42.333333
B49: ='INVENTARIO PISO '!A17 -> 135763 | C49: ='INVENTARIO PISO '!I17 -> 18.8
... B487: ='INVENTARIO PISO '!A455 -> 136474 | C487: ='INVENTARIO PISO '!I455 -> 584
